Workbook
Name Abbas: #REF!
Name ABDELALAIM: #REF!
Name abdelfatah: #REF!
Name abdullah: #REF!
Name ALAA: #REF!
Name all: #REF!
Name alsebea: #REF!
Name Ameen: #REF!
Name asd: #REF!
Name ass: #REF!
Name Cost: #REF!
Name data: #REF!
Name DD: #REF!
Name driver: #REF!
Name finger: #REF!
Name fr: #REF!
Name fre: #REF!
Name HAMIDHAMDY: #REF!
Name IN: #REF!
Name Jahra: #REF!
Name khaled: #REF!
Name kt: 'zone price'!$1:$1048576
Name master: #REF!
Name Mekdad: #REF!
Name MM: #REF!
Name MOHAMED: #REF!
Name ODERS: #REF!
Name OUT: #REF!
Name pnx: #REF!
Name Reports: #REF!
Name rt: #REF!
Name s: #REF!
Name SALIM: #REF!
Name sanad: #REF!
Name SAND: #REF!
Name sas: #REF!
Name wafi: '[1]wafi zone price (2)'!$1:$1048576

Sheet kuwait finder 
A1: # | B1: Governorate | C1: Area-English | D1: Area-Arabic | E1: Postal Code
A2: 1 | B2: Ahmedi Governorate | C2: Abu Halifa | D2: أبو حليفة | E2: =VLOOKUP(C2,'Postal codes'!A:B,2,0) -> 54600
A3: 2 | B3: Ahmedi Governorate | C3: Ahmadi Governorate Desert | D3: بر محافظة الأحمدي | E3: =VLOOKUP(C3,'Postal codes'!A:B,2,0) -> 60000
A4: 3 | B4: Ahmedi Governorate | C4: Al shadadyia Industrial | D4: الشدادية الصناعية | E4: =VLOOKUP(C4,'Postal codes'!A:B,2,0) -> 60000
A5: 4 | B5: Ahmedi Governorate | C5: Al‑Fintas | D5: الفنطاس | E5: =VLOOKUP(C5,'Postal codes'!A:B,2,0) -> 50000
A6: 5 | B6: Ahmedi Governorate | C6: Al-Nuwaiseeb | D6: النويصيب | E6: =VLOOKUP(C6,'Postal codes'!A:B,2,0) -> 50000
A7: 6 | B7: Ahmedi Governorate | C7: Ali Subah Al‑Salem | D7: علي صباح السالم | E7: =VLOOKUP(C7,'Postal codes'!A:B,2,0) -> 65000
A8: 7 | B8: Ahmedi Governorate | C8: Dhaher | D8: الظهر | E8: =VLOOKUP(C8,'Postal codes'!A:B,2,0) -> 51250
A9: 8 | B9: Ahmedi Governorate | C9: Dulay Az Zunif | D9: ضليع الزنيف | E9: =VLOOKUP(C9,'Postal codes'!A:B,2,0) -> 65700
A10: 9 | B10: Ahmedi Governorate | C10: East Ahmadi | D10: شرق الأحمدي | E10: =VLOOKUP(C10,'Postal codes'!A:B,2,0) -> 60000
A11: 10 | B11: Ahmedi Governorate | C11: East Sabah Al-Ahmad | D11: شرق صباح الأحمد | E11: =VLOOKUP(C11,'Postal codes'!A:B,2,0) -> 67500
A12: 11 | B12: Ahmedi Governorate | C12: Egaila | D12: العقيلة | E12: =VLOOKUP(C12,'Postal codes'!A:B,2,0) -> 60000
A13: 12 | B13: Ahmedi Governorate | C13: Fahad Al-Ahmad | D13: فهد الأحمد | E13: =VLOOKUP(C13,'Postal codes'!A:B,2,0) -> 53800
... A225: 224 | B225: Mubarak Al Kabeer Governorate | C225: Wista | D225: المنطقة الوسطى | E225: =VLOOKUP(C225,'Postal codes'!A:B,2,0) -> 92000

Sheet Branch
A1: # | B1: Branch Name In System | C1: Area | D1: Old Name | E1: Arabic | F1: latitude and longitude | G1: Location | H1: Google Address | I1: Postol Code
A2: 1 | B2: Al Nower Pharmacy | C2: Sabah Al Ahmed | D2: aldawaeya pharmacy 89 | E2: صيدلية الدوائية 89 | F2: 28.80144955823426, 48.06402332944741 | G2: https://www.google.com/maps/place/%D8%B5%D9%8A%D8%AF%D9%84%D9%8A%D8%A9+%D8%A7%D9%84%D9%86%D9%88%D9%8A%D8%B1%E2%80%AD/@28.8014454,48.0640971,21z/data=!4m6!3m5!1s0x3fce57ae549171bd:0x3494a9d283db0e94!8m2!3d28.8014388!4d48.064028!16s%2Fg%2F11r9vwnsms!5m1!1e1?entry=ttu&g_ep=EgoyMDI2MDExMy4wIKXMDSoASAFQAw%3D%3D | H2: قطعة 6 , السوق المركزي , محل رقم 1 Sabah Al Ahmad، Kuwait Sabah Al Ahmad, Kuwait, 66386 | I2: 66386
A3: 2 | B3: Al Sultan Pharmacy | C3: Egaila | D3: Al Shifa Al Dawaeya Pharmacy | E3: صيدليه الشفاء دوائيه | F3: 29.173856863564005, 48.0974577235698 | G3: https://www.google.com/maps/place/Shefa+Pharmacy/@29.1735802,48.0972928,18.31z/data=!4m10!1m2!2m1!1sshifa+pharmacy!3m6!1s0x3fcf0a1ed4f1162b:0xddfbe0bd1302af90!8m2!3d29.1737947!4d48.0974209!15sCg5zaGlmYSBwaGFybWFjeVoQIg5zaGlmYSBwaGFybWFjeZIBCHBoYXJtYWN54AEA!16s%2Fg%2F11gd215pzd!5m1!1e1?entry=ttu&g_ep=EgoyMDI2MDExMy4wIKXMDSoASAFQAw%3D%3D | H3: 53FW+GX7, Hadiya | I3: 54200
A4: 3 | B4: Son | C4: Egaila | D4: Sondos pharmacy | E4: صيدليه سندس | F4: 29.17408032318127, 48.09514179712771 | G4: https://www.google.com/maps/place/Aldawaeya+pharmacy/@29.1739714,48.0952491,21z/data=!4m6!3m5!1s0x3fc555d3beecb957:0x2a3f2acf8b349491!8m2!3d29.1740706!4d48.0951047!16s%2Fg%2F11fjsdxmfj!5m1!1e1?entry=ttu&g_ep=EgoyMDI2MDExMy4wIKXMDSoASAFQAw%3D%3D | H4: العقيله شارع 104 مجمع 89 Egia - 4 - 104 - 89 Mall، العقيله | I4: 54200
A5: 4 | B5: May | C5: Egaila | D5: Mays Pharmacy | E5: صيدليه ميس | F5: 29.174470363378028, 48.09429116997421 | G5: https://www.google.com/maps/place/%D8%B5%D9%8A%D8%AF%D9%84%D9%8A%D8%A9+%D9%85%D9%8A%D8%B3%E2%80%AD/@29.1744508,48.0941249,20.74z/data=!4m6!3m5!1s0x3fcf0a1bc882767b:0xe9c71b19f643dce7!8m2!3d29.1744487!4d48.0942907!16s%2Fg%2F11b6g8lhjb!5m1!1e1?entry=ttu&g_ep=EgoyMDI2MDExMy4wIKXMDSoASAFQAw%3D%3D | H5: 104 Rd | I5: 54200
A6: 5 | B6: Mays ST | C6: Egaila | D6: Mays ST | E6: مخزن ميس | F6: 29.174191802039505, 48.09419202946435 | G6: https://www.google.com/maps/place/%D8%B2%D9%87%D9%88%D8%B1+%D8%B3%D8%AA%D8%A7%D9%8A%D9%84%E2%80%AD/@29.1744025,48.0940026,21z/data=!4m14!1m7!3m6!1s0x3fcf0a1bc882767b:0xe9c71b19f643dce7!2z2LXZitiv2YTZitipINmF2YrYsw!8m2!3d29.1744487!4d48.0942907!16s%2Fg%2F11b6g8lhjb!3m5!1s0x3fcf0b0fe22e5aa7:0xf39c5d4e7246672!8m2!3d29.1741864!4d48.0941917!16s%2Fg%2F11fsm25cs5!5m1!1e1!17m2!4m1!1e3!18m1!1e1?entry=ttu&g_ep=EgoyMDI2MDExMy4wIKXMDSoASAFQAw%3D%3D | H6: Road 303, Al-Dora Mall next to Al-Liwan Mall | I6: 54200
A7: 6 | B7: Mas | C7: Sabah Al Salem | D7: Al-Masila pharmacy | E7: صيدليه المسيله | F7: 29.248840577770917, 48.08945603804315 | G7: https://www.google.com/maps/place/Masila+Pharmacy/@29.2487575,48.0891985,21z/data=!4m6!3m5!1s0x3fcf7551c627f41b:0x4bb812a75a6bc0b5!8m2!3d29.2488313!4d48.08944!16s%2Fg%2F11b6gclpjr!5m1!1e1?entry=ttu&g_ep=EgoyMDI2MDExMy4wIKXMDSoASAFQAw%3D%3D | H7: 207, Sabah Al Salem | I7: 44000
A8: 7 | B8: Al Banay Pharmacy | C8: Sabah Al Salem | D8: Sabah Al Salem Al Dawaeya Ph | E8: صيدليه صباح سالم الدوائيه | F8: 29.258726000859145, 48.08592651525166 | G8: https://www.google.com/maps/place/%D8%B5%D9%8A%D8%AF%D9%84%D9%8A%D8%A9+%D8%A7%D9%84%D8%A8%D9%86%D8%A7%D9%8A%E2%80%AD/@29.258764,48.0858427,21z/data=!4m6!3m5!1s0x3fcf7560d2a12765:0x6d57c301989e2f34!8m2!3d29.258717!4d48.0859127!16s%2Fg%2F11h5tn5d4l!5m1!1e1?entry=ttu&g_ep=EgoyMDI2MDExMy4wIKXMDSoASAFQAw%3D%3D | H8: Abdul Aziz Bin Abdulrahman Al Saud Rd, Sabah Al Salem | I8: 44000
A9: 8 | B9: Al Rabee Pharmacy | C9: Salmiya | D9: Al Dawaeya Al Salmiya Pharmacy | E9: صيدليه الدوائيه السالميه | F9: 29.325126099682727, 48.045089741740625 | G9: https://www.google.com/maps/place/%D8%B5%D9%8A%D8%AF%D9%84%D9%8A%D8%A9+%D8%A7%D9%84%D8%B1%D8%A8%D9%8A%D8%B9%E2%80%AD/@29.3263257,48.0438709,17.31z/data=!4m6!3m5!1s0x3fcf9d544d6e7dcd:0x110b5a52ff25ed47!8m2!3d29.3251112!4d48.0450659!16s%2Fg%2F11rnk7ypgr!5m1!1e1?entry=ttu&g_ep=EgoyMDI2MDExMy4wIKXMDSoASAFQAw%3D%3D | H9: Block 011, 30 road Salmiya, 20012 | I9: 20012
A10: 9 | B10: Heba pharmacy | C10: Hawally | D10: Heba pharmacy | E10: صيدليه هبه | F10: 29.347049022512188, 48.01311120689418 | G10: https://www.google.com/maps/place/%D8%B5%D9%8A%D8%AF%D9%84%D9%8A%D8%A9+%D9%87%D8%A8%D8%A9%E2%80%AD/@29.3455714,48.0122529,16.75z/data=!4m14!1m7!3m6!1s0x3fcf9c967b666e25:0x78dc553109e34990!2sHeba+pharmacy!8m2!3d29.3452983!4d48.0154!16s%2Fg%2F11dxst0ds_!3m5!1s0x3fcf9dc0520f123d:0x89fa9f7738f6c543!8m2!3d29.3466672!4d48.0130321!16s%2Fg%2F11pv2xtpvz!5m1!1e1?entry=ttu&g_ep=EgoyMDI2MDExMy4wIKXMDSoASAFQAw%3D%3D | H10: 82W8+456, Hawally | I10: 30000
A11: 10 | B11: Bir | C11: Qurtoba | D11: Al-Biruni Pharmacy | E11: صيدلية البيروني | F11: 29.312037935889943, 47.992319405731884 | G11: https://www.google.com/maps/place/%D8%B5%D9%8A%D8%AF%D9%84%D9%8A%D8%A9+%D8%A7%D9%84%D8%A8%D9%8A%D8%B1%D9%88%D9%86%D9%8A%E2%80%AD/@29.3117931,47.9920422,20.17z/data=!4m7!3m6!1s0x3fcf9b1446be25f9:0x2c7d6b09994f2507!4b1!8m2!3d29.3120211!4d47.9923126!16s%2Fg%2F11sycvr33s!5m1!1e1?entry=ttu&g_ep=EgoyMDI2MDExMy4wIKXMDSoASAFQAw%3D%3D | H11: قرطبة - ق 2- شارع 4 - قسيمة - بناية 4 - الدور الأرضي قرطبة, 73502 | I11: 73502
A12: 11 | B12: Hamza Pharmacy | C12: Khaitan | D12: Khaitan Al Dawaeya Pharmacy | E12: صيدليه حيطان الدوائيه | F12: 29.291521448187375, 47.97451382762952 | G12: https://www.google.com/maps/place/%D8%B5%D9%8A%D8%AF%D9%84%D9%8A%D8%A9+%D8%AD%D9%85%D8%B2%D8%A9%E2%80%AD/@29.2914625,47.9743744,20.96z/data=!4m14!1m7!3m6!1s0x3fcf9b781ff9f73b:0xeb7a25541f0b534!2z2LXZitiv2YTZitipINit2YXYstip!8m2!3d29.2915056!4d47.9745105!16s%2Fg%2F11smtx66d2!3m5!1s0x3fcf9b781ff9f73b:0xeb7a25541f0b534!8m2!3d29.2915056!4d47.9745105!16s%2Fg%2F11smtx66d2!5m1!1e1?entry=ttu&g_ep=EgoyMDI2MDExMy4wIKXMDSoASAFQAw%3D%3D | H12: خيطان ق6 قسيمة 1615 الأرضي | I12: 47800
A13: 12 | B13: Al Madina Pharmacy | C13: Jaleeb Al Shuwaikh | D13: city pharmacy Abbasiya | E13: صيدليه رويال المدينه | F13: 29.258463042154247, 47.93093233653488 | G13: https://www.google.com/maps/place/Royal+City+Clinic+Jleeb+Al-Shuyoukh/@29.2585874,47.9308013,19.22z/data=!4m6!3m5!1s0x3fcf9a02bb64a875:0x78443b61811afd20!8m2!3d29.2584213!4d47.9308126!16s%2Fg%2F11b6nmcpqv!5m1!1e1?entry=ttu&g_ep=EgoyMDI2MDExMy4wIKXMDSoASAFQAw%3D%3D | H13: 7W5J+F54 St, Near Jaleeb Police Station, Khaled Uqab Al Ashhab, Ardiya | I13: 85600

Sheet Postal 
A1: Branch | B1: Area | C1: Region | D1: Postal | E1: Zone
A2: Hamza Pharmacy | B2: khitan | C2: Khaitan | D2: 83000 | E2: Z1
A3: Hamza Pharmacy | B3: khitan | C3: Omariya | D3: 85000 | E3: Z1
A4: Hamza Pharmacy | B4: khitan | C4: Al Farwaniyah | D4: 80000 | E4: Z1
A5: Hamza Pharmacy | B5: khitan | C5: Zahra | D5: 47700 | E5: Z1
A6: Hamza Pharmacy | B6: khitan | C6: Al Siddeeq | D6: 46500 | E6: Z1
A7: Hamza Pharmacy | B7: khitan | C7: Salam | D7: 46300 | E7: Z1
A8: Hamza Pharmacy | B8: khitan | C8: Shuhada | D8: 46400 | E8: Z1
A9: Hamza Pharmacy | B9: khitan | C9: Hateen | D9: 46900 | E9: Z1
A10: Hamza Pharmacy | B10: khitan | C10: Surra | D10: 45400 | E10: Z1
A11: Hamza Pharmacy | B11: khitan | C11: Yarmouk | D11: 45450 | E11: Z1
A12: Hamza Pharmacy | B12: khitan | C12: Al Dajeej | D12: 81000 | E12: Z1
A13: Hamza Pharmacy | B13: khitan | C13: Qortuba | D13: 48100 | E13: Z1
... A1571: Al Nower Pharmacy | B1571: Sabah Al Ahmed | C1571: Al Julaiaa | D1571: 51600 | E1571: Z4

Sheet Drivers
A1: # | B1: Biometric | C1: Phinex Code | D1: Vehichle | E1: Name | F1: Contact | G1: Location | H1: Time In | I1: Time Out | J1: 🧭 Hours
A2: 1 | B2: 2838 | C2: B11 | D2: 🚗 | E2: Ali Ramadan Ali Ibrahim | F2: 96759116 | G2: Sabah Al Ahmed | H2: 0.25 | I2: 0.75 | J2: =MOD(I2-H2,1) -> 0.5
A3: 2 | B3: 7388 | C3: E24 | D3: 🚗 | E3: Assran Ismaiel Ahmed | F3: 67030584 | G3: Sabah Al Ahmed | H3: 0.75 | I3: 0.25 | J3: =MOD(I3-H3,1) -> 0.5
A4: 3 | B4: 7459 | C4: B29 | D4: 🚗 | E4: Ahmed Mahrous | F4: 97570453 | G4: Sabah Al Ahmed | H4: 0.70833333 | I4: 0.20833333 | J4: =MOD(I4-H4,1) -> 0.5
A5: 4 | B5: 1772 | C5: B16 | D5: 🚗 | E5: Gamal Rezk Mohamed | F5: 65787369 | G5: Sabah Al Ahmed | H5: 0.70833333 | I5: 0.20833333 | J5: =MOD(I5-H5,1) -> 0.5
A6: 5 | B6: 2874 | C6: B39 | D6: 🚗 | E6: Hossny Shehata Mohamed | F6: 97593909 | G6: Sabah Al Ahmed | H6: 0.5 | I6: 1 | J6: =MOD(I6-H6,1) -> 0.5
A7: 6 | B7: 7375 | C7: B20 | D7: 🚗 | E7: Khalid Zoalnoon Ahmed | F7: 97202128 | G7: Sabah Al Ahmed | H7: 0.33333333 | I7: 0.83333333 | J7: =MOD(I7-H7,1) -> 0.5
A8: 7 | B8: 7462 | C8: B28 | D8: 🚗 | E8: Abdulkreem Khalid | F8: 98712948 | G8: Sabah Al Ahmed | H8: 0.33333333 | I8: 0.83333333 | J8: =MOD(I8-H8,1) -> 0.5
A9: 8 | B9: 7468 | C9: B38 | D9: 🚗 | E9: Mahmoud Sayed | F9: 66509230 | G9: Sabah Al Ahmed | H9: 0.66666667 | I9: 1 | J9: =MOD(I9-H9,1) -> 0.33333333
A10: 9 | B10: 7470 | C10: B19 | D10: 🚗 | E10: Ahmed Tahwir | F10: 94947606 | G10: Sabah Al Ahmed | H10: 0.625 | I10: 0.125 | J10: =MOD(I10-H10,1) -> 0.5
A11: 10 | B11: 7473 | C11: B15 | D11: 🚗 | E11: Yousif Omer | F11: 98934706 | G11: Sabah Al Ahmed | H11: 0.54166667 | I11: 0.041666667 | J11: =MOD(I11-H11,1) -> 0.5
A12: 11 | B12: 1976 | C12: B9 | D12: 🚗 | E12: Elmardi Osman | F12: 99306075 | G12: Sabah Al Ahmed | H12: 0.75 | I12: 0.25 | J12: =MOD(I12-H12,1) -> 0.5
A13: 12 | B13: 7211 | C13: X73 | D13: 🏍️ | E13: Magdi Ahmed Mokhtar | F13: 94947816 | G13: Sabah Al Ahmed | H13: 0.375 | I13: 0.875 | J13: =MOD(I13-H13,1) -> 0.5
... A103: 102 | B103: 1351 | C103: BC14 | D103: 🚗 | E103: Sawy Abdelzim | F103: 51784392 | G103: Qortuba | H103: 0.25 | I103: 0.75 | J103: =MOD(I103-H103,1) -> 0.5

Sheet Postal Codes 
A1: Area-English | B1: Area-Arabic | C1: Postal Code
A2: Abu Halifa | B2: أبو حليفة | C2: =VLOOKUP(A2,'Postal codes'!A:B,2,0) -> 54600
A3: Ahmadi Governorate Desert | B3: بر محافظة الأحمدي | C3: =VLOOKUP(A3,'Postal codes'!A:B,2,0) -> 60000
A4: Al shadadyia Industrial | B4: الشدادية الصناعية | C4: =VLOOKUP(A4,'Postal codes'!A:B,2,0) -> 60000
A5: Al‑Fintas | B5: الفنطاس | C5: =VLOOKUP(A5,'Postal codes'!A:B,2,0) -> 50000
A6: Al-Nuwaiseeb | B6: النويصيب | C6: =VLOOKUP(A6,'Postal codes'!A:B,2,0) -> 50000
A7: Ali Subah Al‑Salem | B7: علي صباح السالم | C7: =VLOOKUP(A7,'Postal codes'!A:B,2,0) -> 65000
A8: Dhaher | B8: الظهر | C8: =VLOOKUP(A8,'Postal codes'!A:B,2,0) -> 51250
A9: Dulay Az Zunif | B9: ضليع الزنيف | C9: =VLOOKUP(A9,'Postal codes'!A:B,2,0) -> 65700
A10: East Ahmadi | B10: شرق الأحمدي | C10: =VLOOKUP(A10,'Postal codes'!A:B,2,0) -> 60000
A11: East Sabah Al-Ahmad | B11: شرق صباح الأحمد | C11: =VLOOKUP(A11,'Postal codes'!A:B,2,0) -> 67500
A12: Egaila | B12: العقيلة | C12: =VLOOKUP(A12,'Postal codes'!A:B,2,0) -> 60000
A13: Fahad Al-Ahmad | B13: فهد الأحمد | C13: =VLOOKUP(A13,'Postal codes'!A:B,2,0) -> 53800
... A225: Wista | B225: المنطقة الوسطى | C225: =VLOOKUP(A225,'Postal codes'!A:B,2,0) -> 92000

Sheet zone price
A1: Vlooukup | B1: Branch | C1: Region | D1: Zone P | E1: Zone
A2: =B2&"-"&C2 -> Hamza Pharmacy-Khaitan | B2: Hamza Pharmacy | C2: Khaitan | D2: 0.7 | E2: Z1 | I2: Z1 | J2: Z2 | K2: Z3 | L2: Z4
A3: =B3&"-"&C3 -> Hamza Pharmacy-Omariya | B3: Hamza Pharmacy | C3: Omariya | D3: 0.7 | E3: Z1 | G3: Egaila | H3: Al Sultan Pharmacy | I3: =COUNTIFS($B:$B,$H3,$E:$E,I$2) -> 17 | J3: =COUNTIFS($B:$B,$H3,$E:$E,J$2) -> 37 | K3: =COUNTIFS($B:$B,$H3,$E:$E,K$2) -> 48 | L3: =COUNTIFS($B:$B,$H3,$E:$E,L$2) -> 32 | M3: =COUNTIF(B:B,H3) -> 135
A4: =B4&"-"&C4 -> Hamza Pharmacy-Al Farwaniyah | B4: Hamza Pharmacy | C4: Al Farwaniyah | D4: 0.7 | E4: Z1 | G4: Egaila | H4: Son | I4: =COUNTIFS($B:$B,$H4,$E:$E,I$2) -> 17 | J4: =COUNTIFS($B:$B,$H4,$E:$E,J$2) -> 37 | K4: =COUNTIFS($B:$B,$H4,$E:$E,K$2) -> 48 | L4: =COUNTIFS($B:$B,$H4,$E:$E,L$2) -> 32 | M4: =COUNTIF(B:B,H4) -> 135
A5: =B5&"-"&C5 -> Hamza Pharmacy-Zahra | B5: Hamza Pharmacy | C5: Zahra | D5: 0.7 | E5: Z1 | G5: Egaila | H5: Mays ST | I5: =COUNTIFS($B:$B,$H5,$E:$E,I$2) -> 17 | J5: =COUNTIFS($B:$B,$H5,$E:$E,J$2) -> 37 | K5: =COUNTIFS($B:$B,$H5,$E:$E,K$2) -> 48 | L5: =COUNTIFS($B:$B,$H5,$E:$E,L$2) -> 32 | M5: =COUNTIF(B:B,H5) -> 135
A6: =B6&"-"&C6 -> Hamza Pharmacy-Al Siddeeq | B6: Hamza Pharmacy | C6: Al Siddeeq | D6: 0.7 | E6: Z1 | G6: Egaila | H6: Hamza Pharmacy | I6: =COUNTIFS($B:$B,$H6,$E:$E,I$2) -> 15 | J6: =COUNTIFS($B:$B,$H6,$E:$E,J$2) -> 62 | K6: =COUNTIFS($B:$B,$H6,$E:$E,K$2) -> 32 | L6: =COUNTIFS($B:$B,$H6,$E:$E,L$2) -> 10 | M6: =COUNTIF(B:B,H6) -> 119
A7: =B7&"-"&C7 -> Hamza Pharmacy-Salam | B7: Hamza Pharmacy | C7: Salam | D7: 0.7 | E7: Z1 | G7: khaitan | H7: Al Madina Pharmacy | I7: =COUNTIFS($B:$B,$H7,$E:$E,I$2) -> 10 | J7: =COUNTIFS($B:$B,$H7,$E:$E,J$2) -> 51 | K7: =COUNTIFS($B:$B,$H7,$E:$E,K$2) -> 61 | L7: =COUNTIFS($B:$B,$H7,$E:$E,L$2) -> 12 | M7: =COUNTIF(B:B,H7) -> 135
A8: =B8&"-"&C8 -> Hamza Pharmacy-Shuhada | B8: Hamza Pharmacy | C8: Shuhada | D8: 0.7 | E8: Z1 | G8: jaleeb al shuwaikh | H8: Al Banay Pharmacy | I8: =COUNTIFS($B:$B,$H8,$E:$E,I$2) -> 13 | J8: =COUNTIFS($B:$B,$H8,$E:$E,J$2) -> 78 | K8: =COUNTIFS($B:$B,$H8,$E:$E,K$2) -> 23 | L8: =COUNTIFS($B:$B,$H8,$E:$E,L$2) -> 20 | M8: =COUNTIF(B:B,H8) -> 135
A9: =B9&"-"&C9 -> Hamza Pharmacy-Hateen | B9: Hamza Pharmacy | C9: Hateen | D9: 0.7 | E9: Z1 | G9: Sabah Al Salem | H9: Heba pharmacy | I9: =COUNTIFS($B:$B,$H9,$E:$E,I$2) -> 14 | J9: =COUNTIFS($B:$B,$H9,$E:$E,J$2) -> 63 | K9: =COUNTIFS($B:$B,$H9,$E:$E,K$2) -> 43 | L9: =COUNTIFS($B:$B,$H9,$E:$E,L$2) -> 14 | M9: =COUNTIF(B:B,H9) -> 135
A10: =B10&"-"&C10 -> Hamza Pharmacy-Surra | B10: Hamza Pharmacy | C10: Surra | D10: 0.7 | E10: Z1 | G10: Sabah Al Salem | H10: Al Dawaeya Al Jahra Pharmacy | I10: =COUNTIFS($B:$B,$H10,$E:$E,I$2) -> 12 | J10: =COUNTIFS($B:$B,$H10,$E:$E,J$2) -> 18 | K10: =COUNTIFS($B:$B,$H10,$E:$E,K$2) -> 74 | L10: =COUNTIFS($B:$B,$H10,$E:$E,L$2) -> 30 | M10: =COUNTIF(B:B,H10) -> 135
A11: =B11&"-"&C11 -> Hamza Pharmacy-Yarmouk | B11: Hamza Pharmacy | C11: Yarmouk | D11: 0.7 | E11: Z1 | G11: Hawally | H11: Al Rabee Pharmacy | I11: =COUNTIFS($B:$B,$H11,$E:$E,I$2) -> 14 | J11: =COUNTIFS($B:$B,$H11,$E:$E,J$2) -> 63 | K11: =COUNTIFS($B:$B,$H11,$E:$E,K$2) -> 43 | L11: =COUNTIFS($B:$B,$H11,$E:$E,L$2) -> 14 | M11: =COUNTIF(B:B,H11) -> 135
A12: =B12&"-"&C12 -> Hamza Pharmacy-Al Dajeej | B12: Hamza Pharmacy | C12: Al Dajeej | D12: 0.7 | E12: Z1 | G12: Jahra | H12: Consultant Center ST | I12: =COUNTIFS($B:$B,$H12,$E:$E,I$2) -> 14 | J12: =COUNTIFS($B:$B,$H12,$E:$E,J$2) -> 63 | K12: =COUNTIFS($B:$B,$H12,$E:$E,K$2) -> 45 | L12: =COUNTIFS($B:$B,$H12,$E:$E,L$2) -> 14 | M12: =COUNTIF(B:B,H12) -> 137
A13: =B13&"-"&C13 -> Hamza Pharmacy-Qortuba | B13: Hamza Pharmacy | C13: Qortuba | D13: 0.7 | E13: Z1 | G13: Salmiya | H13: Mas | I13: =COUNTIFS($B:$B,$H13,$E:$E,I$2) -> 13 | J13: =COUNTIFS($B:$B,$H13,$E:$E,J$2) -> 78 | K13: =COUNTIFS($B:$B,$H13,$E:$E,K$2) -> 23 | L13: =COUNTIFS($B:$B,$H13,$E:$E,L$2) -> 20 | M13: =COUNTIF(B:B,H13) -> 135
A14: =B14&"-"&C14 -> Hamza Pharmacy-Rabia | B14: Hamza Pharmacy | C14: Rabia | D14: 0.7 | E14: Z1 | G14: Salmiya | H14: Bir | I14: =COUNTIFS($B:$B,$H14,$E:$E,I$2) -> 24 | J14: =COUNTIFS($B:$B,$H14,$E:$E,J$2) -> 51 | K14: =COUNTIFS($B:$B,$H14,$E:$E,K$2) -> 45 | L14: =COUNTIFS($B:$B,$H14,$E:$E,L$2) -> 14 | M14: =COUNTIF(B:B,H14) -> 135
... A16: =B16&"-"&C16 -> Hamza Pharmacy-Abdullah Al Mubarak Al Sabah | B16: Hamza Pharmacy | C16: Abdullah Al Mubarak Al Sabah | D16: 1 | E16: Z2 | G16: Sabah Al Ahmed | H16: Al Nower Pharmacy | I16: =COUNTIFS($B:$B,$H16,$E:$E,I$2) -> 6 | J16: =COUNTIFS($B:$B,$H16,$E:$E,J$2) -> 1 | K16: =COUNTIFS($B:$B,$H16,$E:$E,K$2) -> 4 | L16: =COUNTIFS($B:$B,$H16,$E:$E,L$2) -> 123 | M16: =COUNTIF(B:B,H16) -> 135
A17: =B17&"-"&C17 -> Hamza Pharmacy-West Abdallah Al mubark | B17: Hamza Pharmacy | C17: West Abdallah Al mubark | D17: 1 | E17: Z2
A18: =B18&"-"&C18 -> Hamza Pharmacy-Sulaibiya | B18: Hamza Pharmacy | C18: Sulaibiya | D18: 1 | E18: Z2
A19: =B19&"-"&C19 -> Hamza Pharmacy-Firdous | B19: Hamza Pharmacy | C19: Firdous | D19: 1 | E19: Z2
A20: =B20&"-"&C20 -> Hamza Pharmacy-Ishbiliya | B20: Hamza Pharmacy | C20: Ishbiliya | D20: 1 | E20: Z2
A21: =B21&"-"&C21 -> Hamza Pharmacy-Ardiya | B21: Hamza Pharmacy | C21: Ardiya | D21: 1 | E21: Z2
A22: =B22&"-"&C22 -> Hamza Pharmacy-Sabah Al Nasser | B22: Hamza Pharmacy | C22: Sabah Al Nasser | D22: 1 | E22: Z2
A23: =B23&"-"&C23 -> Hamza Pharmacy-Andalous | B23: Hamza Pharmacy | C23: Andalous | D23: 1 | E23: Z2
A24: =B24&"-"&C24 -> Hamza Pharmacy-Qairawan | B24: Hamza Pharmacy | C24: Qairawan | D24: 1 | E24: Z2
A25: =B25&"-"&C25 -> Hamza Pharmacy-Jeleeb Al Shuyoukh | B25: Hamza Pharmacy | C25: Jeleeb Al Shuyoukh | D25: 1 | E25: Z2
A26: =B26&"-"&C26 -> Hamza Pharmacy-North West Al Sulaibikhat | B26: Hamza Pharmacy | C26: North West Al Sulaibikhat | D26: 1 | E26: Z2
A27: =B27&"-"&C27 -> Hamza Pharmacy-Sulaibikhat | B27: Hamza Pharmacy | C27: Sulaibikhat | D27: 1 | E27: Z2
A28: =B28&"-"&C28 -> Hamza Pharmacy-Jaber Al Ahmad | B28: Hamza Pharmacy | C28: Jaber Al Ahmad | D28: 1 | E28: Z2
... A118: =B118&"-"&C118 -> Hamza Pharmacy-Al Mutla | B118: Hamza Pharmacy | C118: Al Mutla | D118: 1.3 | E118: Z3
A119: =B119&"-"&C119 -> -
A120: =B120&"-"&C120 -> Al Dawaeya Al Jahra Pharmacy-Jaber Al Ahmad | B120: Al Dawaeya Al Jahra Pharmacy | C120: Jaber Al Ahmad | D120: 0.7 | E120: Z1
A121: =B121&"-"&C121 -> Al Dawaeya Al Jahra Pharmacy-Naseem | B121: Al Dawaeya Al Jahra Pharmacy | C121: Naseem | D121: 0.7 | E121: Z1
A122: =B122&"-"&C122 -> Al Dawaeya Al Jahra Pharmacy-Taima | B122: Al Dawaeya Al Jahra Pharmacy | C122: Taima | D122: 0.7 | E122: Z1
A123: =B123&"-"&C123 -> Al Dawaeya Al Jahra Pharmacy-Waha | B123: Al Dawaeya Al Jahra Pharmacy | C123: Waha | D123: 0.7 | E123: Z1
A124: =B124&"-"&C124 -> Al Dawaeya Al Jahra Pharmacy-Oyoun | B124: Al Dawaeya Al Jahra Pharmacy | C124: Oyoun | D124: 0.7 | E124: Z1
A125: =B125&"-"&C125 -> Al Dawaeya Al Jahra Pharmacy-Qasr | B125: Al Dawaeya Al Jahra Pharmacy | C125: Qasr | D125: 0.7 | E125: Z1
A126: =B126&"-"&C126 -> Al Dawaeya Al Jahra Pharmacy-Jahra | B126: Al Dawaeya Al Jahra Pharmacy | C126: Jahra | D126: 0.7 | E126: Z1
A127: =B127&"-"&C127 -> Al Dawaeya Al Jahra Pharmacy-Naeem | B127: Al Dawaeya Al Jahra Pharmacy | C127: Naeem | D127: 0.7 | E127: Z1
A128: =B128&"-"&C128 -> Al Dawaeya Al Jahra Pharmacy-Al Jahra Industrial Area Block 1 | B128: Al Dawaeya Al Jahra Pharmacy | C128: Al Jahra Industrial Area Block 1 | D128: 0.7 | E128: Z1
A129: =B129&"-"&C129 -> Al Dawaeya Al Jahra Pharmacy-Saad Al Abdullah | B129: Al Dawaeya Al Jahra Pharmacy | C129: Saad Al Abdullah | D129: 1 | E129: Z2
A130: =B130&"-"&C130 -> Al Dawaeya Al Jahra Pharmacy-Sulaibiya | B130: Al Dawaeya Al Jahra Pharmacy | C130: Sulaibiya | D130: 1 | E130: Z2
...

Sheet Postal codes
A1: Abu Halifa | B1: 54600 | F1: =TRIM(A1) -> Abu Halifa
A2: Ahmadi | B2: 60000 | F2: =TRIM(A2) -> Ahmadi
A3: Al Shadadyia Industrial | B3: 60000 | F3: =TRIM(A3) -> Al Shadadyia Industrial
A4: Al‑Fintas | B4: 50000 | F4: =TRIM(A4) -> Al‑Fintas
A5: Al-Nuwaiseeb | B5: 50000 | F5: =TRIM(A5) -> Al-Nuwaiseeb
A6: Ali Sabah Al‑Salem | B6: 65000 | F6: =TRIM(A6) -> Ali Sabah Al‑Salem
A7: Dhaher | B7: 51250 | F7: =TRIM(A7) -> Dhaher
A8: Dulay Az Zunif | B8: 65700 | F8: =TRIM(A8) -> Dulay Az Zunif
A9: East Ahmadi | B9: 60000 | F9: =TRIM(A9) -> East Ahmadi
A10: East Sabah Al‑Ahmad | B10: 67500 | F10: =TRIM(A10) -> East Sabah Al‑Ahmad
A11: Egaila | B11: 60000 | F11: =TRIM(A11) -> Egaila
A12: Fahad Al‑Ahmad | B12: 53800 | F12: =TRIM(A12) -> Fahad Al‑Ahmad
... A46: Zoor | B46: 65900 | F46: =TRIM(A46) -> Zoor
F47: =TRIM(A47)
F48: =TRIM(A48)
A49: 📍 Al‑Asimah (Capital) | F49: =TRIM(A49) -> 📍 Al‑Asimah (Capital)
F50: =TRIM(A50)
A51: (Main postal codes where exact town not listed online) | F51: =TRIM(A51) -> (Main postal codes where exact town not listed online)
F52: =TRIM(A52)
A53: Area | B53: Postal Code | F53: =TRIM(A53) -> Area
A54: Abdulla Al‑Salem | B54: 72100 | F54: =TRIM(A54) -> Abdulla Al‑Salem
A55: Adailiya | B55: 73100 | F55: =TRIM(A55) -> Adailiya
A56: Al Bida’a | B56: 25000 | F56: =TRIM(A56) -> Al Bida’a
A57: Al‑Siddiq | B57: 47720 | F57: =TRIM(A57) -> Al‑Siddiq
A58: Bnaid Al‑Qar | B58: 36200 | F58: =TRIM(A58) -> Bnaid Al‑Qar
A59: Daiya | B59: 35300 | F59: =TRIM(A59) -> Daiya
A60: Dasma | B60: 35000 | F60: =TRIM(A60) -> Dasma
A61: Dasman | B61: 15400 | F61: =TRIM(A61) -> Dasman
A62: Doha Residential | B62: 93000 | F62: =TRIM(A62) -> Doha Residential
A63: Faiha | B63: 72700 | F63: =TRIM(A63) -> Faiha
A64: Failaka Island | B64: 25200 | F64: =TRIM(A64) -> Failaka Island
A65: Ghornata | B65: 93500 | F65: =TRIM(A65) -> Ghornata
... A86: Yarmouk | B86: 72500 | F86: =TRIM(A86) -> Yarmouk
F87: =TRIM(A87)
F88: =TRIM(A88)
A89: 📍 Al‑Farwaniyah Governorate | F89: =TRIM(A89) -> 📍 Al‑Farwaniyah Governorate
F90: =TRIM(A90)
A91: Area | B91: Postal Code | F91: =TRIM(A91) -> Area
A92: Abdally | B92: 80000 | F92: =TRIM(A92) -> Abdally
A93: Al Mutlaa Residential | B93: 85000 | F93: =TRIM(A93) -> Al Mutlaa Residential
...
